Workbook
Name MonthToDisplay: 'Sunset Galleria'!$C$1
Name YearToDisplay: 'Marina Del Rey'!$B$1
Name DayToStart: Winery!$E$1
Name DayToStart: 'Blank Calendar'!$E$1
Name MonthToDisplay: 'Blank Calendar'!$C$1
Name DayToStart: Burbank!$E$1
Name MonthToDisplay: 'Marina Del Rey'!$C$1
Name MonthToDisplay: Torrance!$C$1
Name YearToDisplay: 'NoHo West'!$B$1
Name DayToStart: 'So Co'!$E$1
Name YearToDisplay: Azusa!$B$1
Name DayToStart: 'Mission Hills'!$E$1
Name YearToDisplay: 'Moreno Valley'!$B$1
Name YearToDisplay: 'Blank Calendar'!$B$1
Name DayToStart: 'La Verne'!$E$1
Name DayToStart: Torrance!$E$1
Name MonthToDisplay: Lakewood!$C$1
Name MonthToDisplay: #REF!
Name DayToStart: Valencia!$E$1
Name YearToDisplay: 'Woodland Hills'!$B$1
Name YearToDisplay: 'Porter Ranch'!$B$1
Name DayToStart: 'Marina Del Rey'!$E$1
Name MonthToDisplay: Winery!$C$1
Name MonthToDisplay: 'Porter Ranch'!$C$1
Name DayToStart: 'Moreno Valley'!$E$1
Name DayToStart: 'NoHo West'!$E$1
Name YearToDisplay: 'Van Nuys'!$B$1
Name DayToStart: Rialto!$E$1
Name DayToStart: Northridge!$E$1
Name YearToDisplay: Redlands!$B$1
Name YearToDisplay: Lakewood!$B$1
Name YearToDisplay: Valencia!$B$1
Name DayToStart: Lakewood!$E$1
Name YearToDisplay: 'So Co'!$B$1
Name MonthToDisplay: 'La Verne'!$C$1
Name YearToDisplay: #REF!
Name MonthToDisplay: Azusa!$C$1
Name MonthToDisplay: 'Van Nuys'!$C$1
Name MonthToDisplay: Rialto!$C$1
Name DayToStart: 'Woodland Hills'!$E$1
Name DayToStart: 'Van Nuys'!$E$1
Name DayToStart: 'Monterey Park'!$E$1
Name DayToStart: Azusa!$E$1
Name YearToDisplay: Rialto!$B$1
Name YearToDisplay: 'Sunset Galleria'!$B$1
Name MonthToDisplay: Redlands!$C$1
Name DayToStart: Eastvale!$E$1
Name MonthToDisplay: 'Moreno Valley'!$C$1
Name YearToDisplay: Northridge!$B$1
Name YearToDisplay: 'Monterey Park'!$B$1
Name DayToStart: Redlands!$E$1
Name YearToDisplay: 'La Verne'!$B$1
Name MonthToDisplay: 'NoHo West'!$C$1
Name DayToStart: 'Sunset Galleria'!$E$1
Name MonthToDisplay: 'Monterey Park'!$C$1
Name MonthToDisplay: Northridge!$C$1
Name MonthToDisplay: 'Woodland Hills'!$C$1
Name YearToDisplay: 'West Covina'!$B$1
Name YearToDisplay: Winery!$B$1
Name MonthToDisplay: 'Mission Hills'!$C$1

Sheet ScheduleLookup
A1: Name | B1: Location | C1: Date
A2: Doug | B2: Azusa | C2: 46174
A3: Lundin | B3: Azusa | C3: 46174
A4: Mortenson | B4: Burbank | C4: 46174
A5: Yesenia | B5: Burbank | C5: 46174
A6: Kendia | B6: Eastvale | C6: 46174
A7: Vich | B7: Eastvale | C7: 46174
A8: Gee | B8: La Verne | C8: 46174
A9: Melinda | B9: La Verne | C9: 46174
A10: Katyln | B10: Lakewood | C10: 46174
A11: Ontiveros | B11: Lakewood | C11: 46174
A12: Calin | B12: Marina Del Rey | C12: 46174
A13: Mazhar | B13: Marina Del Rey | C13: 46174
... A3772: Laura | B3772: Woodland Hills | C3772: 46264

Sheet CovSummary
A1: Coverage Summary
A2: Yellow-highlighted schedule cells only.
A4: Name | B4: Location | C4: Date
A5: Kalapp | B5: NoHo West | C5: 46174
A6: Karen | B6: Rialto | C6: 46174
A7: Madi | B7: Rialto | C7: 46174
A8: Dr. Lam | B8: So Co | C8: 46174
A9: Muzsnai | B9: Valencia | C9: 46174
A10: Brian | B10: Eastvale | C10: 46175
A11: Dr. Peng | B11: NoHo West | C11: 46175
A12: Lehnberg | B12: Torrance | C12: 46175
A13: Lorraine | B13: Monterey Park | C13: 46176
A14: Kalapp | B14: NoHo West | C14: 46176
A15: June | B15: Sunset Galleria | C15: 46176
A16: Lehnberg | B16: Torrance | C16: 46176
... A130: Dalton | B130: Van Nuys | C130: 46264

Sheet OverSched
A1: Over-Scheduled List
A2: Flags 6-day Monday-Sunday violations and same-day multi-location scheduling conflicts.
A4: Issue Type | B4: Name | C4: Date or Week Start Date | D4: Week End Date | E4: Count | F4: Scheduled Dates | G4: Locations Involved | H4: Issue / Warning
A5: 6-Day Rule | B5: Bergstrom | C5: 46174 | D5: 46180 | E5: 6 | F5: 2026-06-02, 2026-06-03, 2026-06-04, 2026-06-05, 2026-06-06, 2026-06-07 | G5: La Verne | H5: Scheduled 6 days in a row within the same Monday-Sunday week.
A6: Same-Day Conflict | B6: Muzsnai | C6: 46175 | D6: 46175 | E6: 2 | F6: 46175 | G6: Mission Hills, Porter Ranch | H6: Double scheduled on the same date across multiple locations.
A7: Same-Day Conflict | B7: Dania | C7: 46176 | D7: 46176 | E7: 2 | F7: 46176 | G7: Mission Hills, Woodland Hills | H7: Double scheduled on the same date across multiple locations.
A8: Same-Day Conflict | B8: Lorraine | C8: 46178 | D8: 46178 | E8: 2 | F8: 46178 | G8: Monterey Park, Sunset Galleria | H8: Double scheduled on the same date across multiple locations.
A9: Same-Day Conflict | B9: Dalton | C9: 46180 | D9: 46180 | E9: 2 | F9: 46180 | G9: Northridge, Porter Ranch | H9: Double scheduled on the same date across multiple locations.
A10: Same-Day Conflict | B10: Melissa | C10: 46180 | D10: 46180 | E10: 2 | F10: 46180 | G10: Northridge, Porter Ranch | H10: Double scheduled on the same date across multiple locations.
A11: 6-Day Rule | B11: Madi | C11: 46181 | D11: 46187 | E11: 6 | F11: 2026-06-09, 2026-06-10, 2026-06-11, 2026-06-12, 2026-06-13, 2026-06-14 | G11: Redlands, Rialto, Winery | H11: Scheduled 6 days in a row within the same Monday-Sunday week.
A12: Same-Day Conflict | B12: Laura | C12: 46184 | D12: 46184 | E12: 2 | F12: 46184 | G12: Mission Hills, Van Nuys | H12: Double scheduled on the same date across multiple locations.
A13: Same-Day Conflict | B13: Peng | C13: 46186 | D13: 46186 | E13: 2 | F13: 46186 | G13: Rialto, Winery | H13: Double scheduled on the same date across multiple locations.
A14: Same-Day Conflict | B14: Laura | C14: 46190 | D14: 46190 | E14: 2 | F14: 46190 | G14: Mission Hills, Northridge | H14: Double scheduled on the same date across multiple locations.
A15: Same-Day Conflict | B15: Laura | C15: 46191 | D15: 46191 | E15: 2 | F15: 46191 | G15: Mission Hills, Van Nuys | H15: Double scheduled on the same date across multiple locations.
A16: Same-Day Conflict | B16: Karen | C16: 46192 | D16: 46192 | E16: 2 | F16: 46192 | G16: Torrance, West Covina | H16: Double scheduled on the same date across multiple locations.
A17: Same-Day Conflict | B17: Laura | C17: 46198 | D17: 46198 | E17: 2 | F17: 46198 | G17: Mission Hills, Van Nuys | H17: Double scheduled on the same date across multiple locations.
A18: Same-Day Conflict | B18: Carrillo | C18: 2026-08-12 | D18: 2026-08-12 | E18: 2 | F18: 2026-08-12 | G18: Northridge, Woodland Hills | H18: Double scheduled on the same date across multiple locations.
A19: Same-Day Conflict | B19: Carrillo | C19: 2026-08-13 | D19: 2026-08-13 | E19: 2 | F19: 2026-08-13 | G19: Northridge, Woodland Hills | H19: Double scheduled on the same date across multiple locations.
A20: Same-Day Conflict | B20: Claudia | C20: 2026-08-15 | D20: 2026-08-15 | E20: 2 | F20: 2026-08-15 | G20: Moreno Valley, So Co | H20: Double scheduled on the same date across multiple locations.
A21: Same-Day Conflict | B21: Juan | C21: 2026-08-18 | D21: 2026-08-18 | E21: 2 | F21: 2026-08-18 | G21: Azusa, La Verne | H21: Double scheduled on the same date across multiple locations.
A22: Same-Day Conflict | B22: Claudia | C22: 2026-08-22 | D22: 2026-08-22 | E22: 2 | F22: 2026-08-22 | G22: Moreno Valley, So Co | H22: Double scheduled on the same date across multiple locations.
A23: Same-Day Conflict | B23: Juan | C23: 2026-08-25 | D23: 2026-08-25 | E23: 2 | F23: 2026-08-25 | G23: Azusa, La Verne | H23: Double scheduled on the same date across multiple locations.
A24: Same-Day Conflict | B24: Claudia | C24: 2026-08-29 | D24: 2026-08-29 | E24: 2 | F24: 2026-08-29 | G24: Moreno Valley, So Co | H24: Double scheduled on the same date across multiple locations.
A25: Same-Day Conflict | B25: Dalton | C25: 2026-08-30 | D25: 2026-08-30 | E25: 2 | F25: 2026-08-30 | G25: Northridge, Van Nuys | H25: Double scheduled on the same date across multiple locations.

Sheet HrsSummary
A1: Hours Summary
A2: Estimated only. Weekday=8 hours, weekend=6.5 hours. Two-week anchor: 2026-06-01.
A4: Name | B4: 2-Week Period Start | C4: 2-Week Period End | D4: Weekday Scheduled Days | E4: Weekend Scheduled Days | F4: Total Scheduled Days | G4: Estimated Hours | H4: Locations Scheduled
A5: Adriana | B5: 46174 | C5: 46187 | D5: 3 | E5: 1 | F5: 4 | G5: 30.5 | H5: Mission Hills
A6: Adriana | B6: 46188 | C6: 46201 | D6: 6 | E6: 2 | F6: 8 | G6: 61 | H6: Mission Hills
A7: Adriana | B7: 46202 | C7: 46215 | D7: 5 | E7: 1 | F7: 6 | G7: 46.5 | H7: Mission Hills
A8: Adriana | B8: 46216 | C8: 46229 | D8: 6 | E8: 2 | F8: 8 | G8: 61 | H8: Mission Hills
A9: Adriana | B9: 46230 | C9: 46243 | D9: 6 | E9: 2 | F9: 8 | G9: 61 | H9: Mission Hills
A10: Adriana | B10: 46244 | C10: 46257 | D10: 6 | E10: 2 | F10: 8 | G10: 61 | H10: Mission Hills
A11: Adriana | B11: 46258 | C11: 46271 | D11: 3 | E11: 1 | F11: 4 | G11: 30.5 | H11: Mission Hills
A12: Andres | B12: 46202 | C12: 46215 | D12: 3 | E12: 0 | F12: 3 | G12: 24 | H12: So Co
A13: Andres | B13: 46216 | C13: 46229 | D13: 6 | E13: 0 | F13: 6 | G13: 48 | H13: So Co
A14: Andres | B14: 46230 | C14: 46243 | D14: 6 | E14: 0 | F14: 6 | G14: 48 | H14: So Co
A15: Andres | B15: 46244 | C15: 46257 | D15: 6 | E15: 0 | F15: 6 | G15: 48 | H15: So Co
A16: Andres | B16: 46258 | C16: 46271 | D16: 4 | E16: 0 | F16: 4 | G16: 32 | H16: So Co
... A670: Yesenia | B670: 46258 | C670: 46271 | D670: 6 | E670: 0 | F670: 6 | G670: 48 | H670: Burbank

Sheet CoverageNeeded
A1: Coverage Type | B1: Location | C1: Date | D1: Potential Candidates | E1: Potential Candidates
A2: WC | B2: Mission Hills | C2: 46175 | D2: Angela, Claudia, Crystal, Dania, Estrella, Fio, Jodryn, Jordyn, Juan, June, Karen, Kendia, Lauren, Leigha, Lidia, Lorraine Bauleth Yesenia, Marissa, Matthew, Melia, Melissa, Rebecca, Steve | E2: Angela, Claudia, Crystal, Dania, Estrella, Fio, Jodryn, Jordyn, Juan, June, Karen, Kendia, Lauren, Leigha, Lidia, Lorraine Bauleth Yesenia, Marissa, Matthew, Melia, Melissa, Rebecca, Steve
A3: DC | B3: Torrance | C3: 46177 | D3: Carhtron, Carlson, Chapman, Cole, Danny, Dewitt, Dr. Bezzic, Dr. K, Dr. Lam, Dr. Malinarich, Dr.K, Fantasia, Garatti, Keenan, Kemper, Kim, Lam, Lehnberg, Ludin, Lundin, Ly, Malinarch, Minassian, Musznai, Musznia, Sal, Salehi, Tolbirt, Wafers, Win | E3: Carhtron, Carlson, Chapman, Cole, Danny, Dewitt, Dr. Bezzic, Dr. K, Dr. Lam, Dr. Malinarich, Dr.K, Fantasia, Garatti, Keenan, Kemper, Kim, Lam, Lehnberg, Ludin, Lundin, Ly, Malinarch, Minassian, Musznai, Musznia, Sal, Salehi, Tolbirt, Wafers, Win
A4: DC | B4: Sunset Galleria | C4: 46178 | D4: Bystrom, Carhtron, Carrillo, Carthron, Chapman, Cole, Cortez, Dalton, Danny, Dewitt, Dr. Bezzic, Dr. K, Dr. Lam, Dr. Malinarich, Dr.K, Fantasia, Gee, Kemper, Kim, Lehnberg, Ludin, Ly, Malinarch, Mortenson, Musznai, Musznia, Muzsnai, Ontiveros, Peng, Salehi, Tulloss, Win | E4: Bystrom, Carhtron, Carrillo, Carthron, Chapman, Cole, Cortez, Dalton, Danny, Dewitt, Dr. Bezzic, Dr. K, Dr. Lam, Dr. Malinarich, Dr.K, Fantasia, Gee, Kemper, Kim, Lehnberg, Ludin, Ly, Malinarch, Mortenson, Musznai, Musznia, Muzsnai, Ontiveros, Peng, Salehi, Tulloss, Win
A5: DC | B5: Torrance | C5: 46178 | D5: Bystrom, Carhtron, Carrillo, Carthron, Chapman, Cole, Cortez, Dalton, Danny, Dewitt, Dr. Bezzic, Dr. K, Dr. Lam, Dr. Malinarich, Dr.K, Fantasia, Gee, Kemper, Kim, Lehnberg, Ludin, Ly, Malinarch, Mortenson, Musznai, Musznia, Muzsnai, Ontiveros, Peng, Salehi, Tulloss, Win | E5: Bystrom, Carhtron, Carrillo, Carthron, Chapman, Cole, Cortez, Dalton, Danny, Dewitt, Dr. Bezzic, Dr. K, Dr. Lam, Dr. Malinarich, Dr.K, Fantasia, Gee, Kemper, Kim, Lehnberg, Ludin, Ly, Malinarch, Mortenson, Musznai, Musznia, Muzsnai, Ontiveros, Peng, Salehi, Tulloss, Win
A6: DC | B6: NoHo West | C6: 46179 | D6: Bystrom, Carhtron, Carlson, Carrillo, Chang, Chapman, Cole, Cortez, Dalton, Danny, Dewitt, Dr. Bezzic, Dr. K, Dr. Lam, Dr. Malinarich, Dr.K, Fantasia, Kemper, Kim, Lehnberg, Ludin, Lundin, Malinarch, Mortenson, Musznai, Musznia, Muzsnai, Ontiveros, Salehi, Tulloss, Win | E6: Bystrom, Carhtron, Carlson, Carrillo, Chang, Chapman, Cole, Cortez, Dalton, Danny, Dewitt, Dr. Bezzic, Dr. K, Dr. Lam, Dr. Malinarich, Dr.K, Fantasia, Kemper, Kim, Lehnberg, Ludin, Lundin, Malinarch, Mortenson, Musznai, Musznia, Muzsnai, Ontiveros, Salehi, Tulloss, Win
A7: DC | B7: Sunset Galleria | C7: 46179 | D7: Bystrom, Carhtron, Carlson, Carrillo, Chang, Chapman, Cole, Cortez, Dalton, Danny, Dewitt, Dr. Bezzic, Dr. K, Dr. Lam, Dr. Malinarich, Dr.K, Fantasia, Kemper, Kim, Lehnberg, Ludin, Lundin, Malinarch, Mortenson, Musznai, Musznia, Muzsnai, Ontiveros, Salehi, Tulloss, Win | E7: Bystrom, Carhtron, Carlson, Carrillo, Chang, Chapman, Cole, Cortez, Dalton, Danny, Dewitt, Dr. Bezzic, Dr. K, Dr. Lam, Dr. Malinarich, Dr.K, Fantasia, Kemper, Kim, Lehnberg, Ludin, Lundin, Malinarch, Mortenson, Musznai, Musznia, Muzsnai, Ontiveros, Salehi, Tulloss, Win
A8: DC | B8: Van Nuys | C8: 46179 | D8: Bystrom, Carhtron, Carlson, Carrillo, Chang, Chapman, Cole, Cortez, Dalton, Danny, Dewitt, Dr. Bezzic, Dr. K, Dr. Lam, Dr. Malinarich, Dr.K, Fantasia, Kemper, Kim, Lehnberg, Ludin, Lundin, Malinarch, Mortenson, Musznai, Musznia, Muzsnai, Ontiveros, Salehi, Tulloss, Win | E8: Bystrom, Carhtron, Carlson, Carrillo, Chang, Chapman, Cole, Cortez, Dalton, Danny, Dewitt, Dr. Bezzic, Dr. K, Dr. Lam, Dr. Malinarich, Dr.K, Fantasia, Kemper, Kim, Lehnberg, Ludin, Lundin, Malinarch, Mortenson, Musznai, Musznia, Muzsnai, Ontiveros, Salehi, Tulloss, Win
A9: DC | B9: NoHo West | C9: 46186 | D9: Bystrom, Carhtron, Carlson, Chang, Chapman, Cole, Cortez, Dalton, Danny, Delector, Dr. Bezzic, Dr. K, Dr. Lam, Dr. Malinarich, Dr.K, Fantasia, Kalapp, Kemper, Lehnberg, Ludin, Lundin, Malinarch, Mortenson, Moursalian, Musznai, Musznia, Muzsnai, Ontiveros, Salehi, Tulloss, Win | E9: Bystrom, Carhtron, Carlson, Chang, Chapman, Cole, Cortez, Dalton, Danny, Delector, Dr. Bezzic, Dr. K, Dr. Lam, Dr. Malinarich, Dr.K, Fantasia, Kalapp, Kemper, Lehnberg, Ludin, Lundin, Malinarch, Mortenson, Moursalian, Musznai, Musznia, Muzsnai, Ontiveros, Peng, Salehi, Tulloss, Win
A10: WC | B10: So Co | C10: 46186 | D10: Ariana, Bobbi, Brian, Crystal, Estrella, Genesis, Jordyn, Juan, Kathy, Katyln, Lorraine Bauleth Yesenia, Lucia, Matthew, Mel, Melia, Rebecca, Steve, Steven | E10: Ariana, Bobbi, Brian, Crystal, Estrella, Genesis, Jordyn, Juan, Kathy, Katyln, Laura, Lorraine Bauleth Yesenia, Lucia, Matthew, Mel, Melia, Rebecca, Steve, Steven
A11: DC | B11: Sunset Galleria | C11: 46186 | D11: Bystrom, Carhtron, Carlson, Chang, Chapman, Cole, Cortez, Dalton, Danny, Delector, Dr. Bezzic, Dr. K, Dr. Lam, Dr. Malinarich, Dr.K, Fantasia, Kalapp, Kemper, Lehnberg, Ludin, Lundin, Malinarch, Mortenson, Moursalian, Musznai, Musznia, Muzsnai, Ontiveros, Salehi, Tulloss, Win | E11: Bystrom, Carhtron, Carlson, Chang, Chapman, Cole, Cortez, Dalton, Danny, Delector, Dr. Bezzic, Dr. K, Dr. Lam, Dr. Malinarich, Dr.K, Fantasia, Kalapp, Kemper, Lehnberg, Ludin, Lundin, Malinarch, Mortenson, Moursalian, Musznai, Musznia, Muzsnai, Ontiveros, Peng, Salehi, Tulloss, Win
A12: WC | B12: Winery | C12: 46187 | D12: Ariana, Ashley, Bobbi, Brian, Calin, Chantel, Crystal, Dania, Doug, Estrella, Genesis, Jaidyn, Jodryn, Jordyn, Juan, June, Karen, Kathy, Katyln, Leigha, Lorraine, Lorraine Bauleth Yesenia, Lucia, Marissa, Matthew, Mel, Melia, Melissa, Rebeca, Rebecca, Steve, Steven, Yesenia | E12: Ariana, Ashley, Bobbi, Brian, Calin, Chantel, Crystal, Dania, Doug, Estrella, Genesis, Jaidyn, Jodryn, Jordyn, Juan, June, Karen, Kathy, Katyln, Leigha, Lorraine, Lorraine Bauleth Yesenia, Lucia, Marissa, Matthew, Mel, Melia, Melissa, Rebeca, Rebecca, Steve, Steven, Yesenia
A13: DC | B13: NoHo West | C13: 46193 | D13: Bystrom, Carhtron, Carlson, Chang, Cole, Cortez, Dalton, Danny, Delector, Dr. Bezzic, Dr. K, Dr. Lam, Dr. Malinarich, Dr.K, Fantasia, Kemper, Lam, Lehnberg, Ludin, Lundin, Malinarch, Mortenson, Musznai, Musznia, Muzsnai, Ontiveros, Sal, Salehi, Tolbirt, Tulloss, Win | E13: Bystrom, Carhtron, Carlson, Chang, Cole, Cortez, Dalton, Danny, Delector, Dr. Bezzic, Dr. K, Dr. Lam, Dr. Malinarich, Dr.K, Fantasia, Kemper, Lam, Lehnberg, Ludin, Lundin, Malinarch, Mortenson, Musznai, Musznia, Muzsnai, Ontiveros, Sal, Salehi, Tolbirt, Tulloss, Win
... A109: WC | B109: Burbank | C109: 46264 | D109: Sunday | E109: Angela, Brian, Claudia, Dania, Doug, Estrella, Fio, Jodryn, Jordyn, Karen, Lauren, Leigha, Lidia, Lorraine, Lorraine Bauleth Yesenia, Marissa, Matthew, Melia, Rebeca, Steve, Steven, Yesenia

Sheet Blank Calendar
B1: =YEAR(TODAY()) -> 2026 | C1: JULY | E1: MONDAY
B2: CALENDAR YEAR | C2: CALENDAR MONTH | E2: FIRST DAY OF WEEK
B3: {=TEXT(B4,"dddd")} -> Monday | C3: =TEXT(C4,"dddd") -> Tuesday | D3: =TEXT(D4,"dddd") -> Wednesday | E3: =TEXT(E4,"dddd") -> Thursday | F3: =TEXT(F4,"dddd") -> Friday | G3: =TEXT(G4,"dddd") -> Saturday | H3: =TEXT(H4,"dddd") -> Sunday
B4: {=DATE($B$1,MATCH(UPPER($C$1),{"JANUARY","FEBRUARY","MARCH","APRIL","MAY","JUNE","JULY","AUGUST","SEPTEMBER","OCTOBER","NOVEMBER","DECEMBER"},0),1)-MOD(WEEKDAY(DATE($B$1,MATCH(UPPER($C$1),{"JANUARY","FEBRUARY","MARCH","APRIL","MAY","JUNE","JULY","AUGUST","SEPTEMBER","OCTOBER","NOVEMBER","DECEMBER"},0),1),2)-MATCH(UPPER($E$1),{"MONDAY","TUESDAY","WEDNESDAY","THURSDAY","FRIDAY","SATURDAY","SUNDAY"},0),7)} -> 46202 | C4: =B4+1 -> 46203 | D4: =C4+1 -> 46204 | E4: =D4+1 -> 46205 | F4: =E4+1 -> 46206 | G4: =F4+1 -> 46207 | H4: =G4+1 -> 46208
A5: Doctor/DC
A6: WC/SWC
B7: =B4+7 -> 46209 | C7: =C4+7 -> 46210 | D7: =D4+7 -> 46211 | E7: =E4+7 -> 46212 | F7: =F4+7 -> 46213 | G7: =G4+7 -> 46214 | H7: =H4+7 -> 46215
A8: Doctor/DC
A9: WC/SWC
B10: {=B7+7} -> 46216 | C10: =C7+7 -> 46217 | D10: =D7+7 -> 46218 | E10: =E7+7 -> 46219 | F10: =F7+7 -> 46220 | G10: =G7+7 -> 46221 | H10: =H7+7 -> 46222
A11: Doctor/DC
A12: WC/SWC
B13: =B10+7 -> 46223 | C13: =C10+7 -> 46224 | D13: =D10+7 -> 46225 | E13: =E10+7 -> 46226 | F13: =F10+7 -> 46227 | G13: =G10+7 -> 46228 | H13: =H10+7 -> 46229
A14: Doctor/DC
A15: WC/SWC
B16: =B13+7 -> 46230 | C16: =C13+7 -> 46231 | D16: =D13+7 -> 46232 | E16: =E13+7 -> 46233 | F16: =F13+7 -> 46234 | G16: =G13+7 -> 46235 | H16: =H13+7 -> 46236
A17: Doctor/DC
A18: WC/SWC
B19: =B16+7 -> 46237 | C19: =C16+7 -> 46238 | D19: =D16+7 -> 46239 | E19: =E16+7 -> 46240 | F19: =F16+7 -> 46241 | G19: =G16+7 -> 46242 | H19: =H16+7 -> 46243
A20: Doctor/DC
A21: WC/SWC

Sheet PTO Requests
A1: Name | B1: Dates | C1: Clinic(s) | D1: Covered/by who/what dates?
A2: Dr. Ivan Malinarich | B2: 6/19-6/21 | C2: Woodland Hills | D2: Y Dr. Alyssa will cover
A3: Dr. Adam DeWitt | B3: 46173 | C3: Torrance | D3: Y
A4: Lauren Walker | B4: 5/18-5/21 | C4: Lakewood | D4: Y
A5: Dr. Michael Kemper | B5: 46166 | C5: Torrance | D5: N
A6: Dr Cole | B6: 5/26-6/4 | C6: NoHo | D6: N
A7: Kori Mortenson, DC | B7: 46201 | C7: Burbank | D7: Y Dr Carlson
A8: Dr. Seog Woo Kim | B8: 5/25, 6/4,6/5 | C8: Sunset | D8: N
A9: Ariana Aguero | B9: 5/21-5/25 | C9: Torrance | D9: 5/21 N, 5/22 Y, 5/25 N
A10: Ariana Aguero | B10: 46183 | C10: Torrance | D10: ?
A11: Genesis Bustos | B11: 5/15, 5/16, 6/5 | C11: Winery | D11: Y 5/15, N 5/16, Y 6/5
A12: Dr. Khodayar Khatiblou* | B12: 6/5, 6/6 | C12: South Corona | D12: N
A13: Estrella Ramirez* | B13: 5/20, 5/27, 5/29, 6/1 | C13: Eastvale | D13: ?
A14: Dr. Jack Bergstrom | B14: 46165 | C14: La Verne | D14: Y
A15: Dr. Danny Duong* | B15: 6/13,6/14,6/20,6/21 | C15: Redlands | D15: N
A16: Kendia Cruz | B16: 6/7, 6/8 | C16: Eastvale | D16: 6/7, 6/8
A17: Marissa Bustos* | B17: 46158 | C17: Rialto | D17: Y
A18: Dr. Anthony Moursalian* | B18: 5/16, 6/26, 6/27,6/30,7/3,7/28 | C18: Rialto | D18: Y 5/16
A19: Dr. Anthony Moursalian | B19: 5/20 (off after 2), 6/13 (off after 130), 7/18 (off after 130) | C19: Rialto | D19: 5/20 covered
A20: Calin Herrera | B20: 46225 | C20: Marina Del Rey | D20: Y, June Moscov
A21: Dania Al-Dhaif | B21: 7/1-7/6 | C21: Woodland Hills | D21: Fio covering July 1st and 2nd, requested on Worklio!
A22: June Black Out Days: Friday 6/5 Saturday 6/13 Saturday 6/20 as of 5.11.26
A25: Dr. Bystrom | B25: 6/30-7/8 | D25: N
A26: Ariana Aguero | B26: 7/2-7/3 & 7/6 | C26: Torrance
A27: Dr. Andrew Lam | B27: 6/4 and 6/16 | C27: Soco, Winery
A28: Melanie Mojarro | B28: 46186 | C28: Soco
A29: Dr. Delector* | B29: 06/11-07/5 | C29: The Redlands | D29: Already Planned Tickets bought
A30: Dr. Adam DeWitt | B30: 6/1-6/8 | C30: Torrance | D30: Submitted via email 04/28
A31: Jaidyn Batchelor | B31: 46187 | C31: Winery Estates | D31: Y ( Approved 05/20/206 )
A32: Dr. Alyssa Carrillo | B32: 7/8-7/9 | C32: Woodland Hills | D32: Couldn't get this to submit on Worklio, Needs Coverage
A33: Dania Al-Dhaif | B33: 46169 | C33: Woodland Hills | D33: Fio Covering
A34: Yesenia Luna | B34: 7/1-7/6 | C34: Burbank | D34: Asked Laura Barr to help cover and she will get back to me on the dates
A35: Dr. Kalapp | B35: 6/11-6/13 | C35: Northridge | D35: coverage found
A36: Dr. Kalapp | B36: 6/25-6/27 | C36: Northridge | D36: coverage found
A37: Crystal Volanos | B37: 46175 | C37: West Covina | D37: Sumbitted via worklion need coverage
A38: Dr. Win | B38: 46159 | C38: Eastvale | D38: Had requested Sunday off previously with Damon
A39: Dr. Khodayar Khatiblou | B39: 10/9, 10/10 | C39: South Corona
A40: Steven Picazo WC | B40: 06/13-06/14 | C40: Redlands
A41: Dr. Aleta Bezzic, SDC | B41: 5/30-6/16 | C41: Menifee | D41: Steve has already arranged coverage (was requested several months ago already)
A42: Carthtron | B42: 46291 | C42: Redlands
...

Sheet La Verne
B1: =YEAR(TODAY()) -> 2026 | C1: JUNE | E1: MONDAY | F1: La Verne | G1: Lockbox Code: | H1: SWC: Brian SDC: Dr. Bezzic | I1: x
B2: CALENDAR YEAR | C2: CALENDAR MONTH | E2: FIRST DAY OF WEEK
B3: {=TEXT(B4,"dddd")} -> Monday | C3: =TEXT(C4,"dddd") -> Tuesday | D3: =TEXT(D4,"dddd") -> Wednesday | E3: =TEXT(E4,"dddd") -> Thursday | F3: =TEXT(F4,"dddd") -> Friday | G3: =TEXT(G4,"dddd") -> Saturday | H3: =TEXT(H4,"dddd") -> Sunday
B4: {=DATE($B$1,MATCH(UPPER($C$1),{"JANUARY","FEBRUARY","MARCH","APRIL","MAY","JUNE","JULY","AUGUST","SEPTEMBER","OCTOBER","NOVEMBER","DECEMBER"},0),1)-MOD(WEEKDAY(DATE($B$1,MATCH(UPPER($C$1),{"JANUARY","FEBRUARY","MARCH","APRIL","MAY","JUNE","JULY","AUGUST","SEPTEMBER","OCTOBER","NOVEMBER","DECEMBER"},0),1),2)-MATCH(UPPER($E$1),{"MONDAY","TUESDAY","WEDNESDAY","THURSDAY","FRIDAY","SATURDAY","SUNDAY"},0),7)} -> 46174 | C4: =B4+1 -> 46175 | D4: =C4+1 -> 46176 | E4: =D4+1 -> 46177 | F4: =E4+1 -> 46178 | G4: =F4+1 -> 46179 | H4: =G4+1 -> 46180
B5: Gee | C5: Bergstrom | D5: Bergstrom | E5: Bergstrom | F5: Bergstrom | G5: Bergstrom | H5: Bergstrom
B6: Melinda | C6: Jaidyn | D6: Jaidyn | E6: Karen | F6: Jaidyn | G6: Jaidyn | H6: Brian
B7: {=B4+7} -> 46181 | C7: =C4+7 -> 46182 | D7: =D4+7 -> 46183 | E7: =E4+7 -> 46184 | F7: =F4+7 -> 46185 | G7: =G4+7 -> 46186 | H7: =H4+7 -> 46187
B8: Gee | C8: Bergstrom | D8: Bergstrom | E8: Bergstrom | F8: Bergstrom | G8: Bergstrom | H8: Gee
B9: Juan | C9: Juan | D9: Jaidyn | E9: Doug | F9: Jaidyn | G9: Jaidyn | H9: Kendia
B10: {=B7+7} -> 46188 | C10: =C7+7 -> 46189 | D10: =D7+7 -> 46190 | E10: =E7+7 -> 46191 | F10: =F7+7 -> 46192 | G10: =G7+7 -> 46193 | H10: =H7+7 -> 46194
B11: Gee | C11: Bergstrom | D11: Bergstrom | E11: Bergstrom | F11: Bergstrom | G11: Bergstrom | H11: CLOSED
B12: Juan | C12: Juan | D12: Jaidyn | E12: Doug | F12: Jaidyn | G12: Jaidyn | H12: CLOSED
B13: {=B10+7} -> 46195 | C13: =C10+7 -> 46196 | D13: =D10+7 -> 46197 | E13: =E10+7 -> 46198 | F13: =F10+7 -> 46199 | G13: =G10+7 -> 46200 | H13: =H10+7 -> 46201
B14: Gee | C14: Bergstrom | D14: Bergstrom | E14: Bergstrom | F14: Bergstrom | G14: Bergstrom | H14: CLOSED
B15: Juan | C15: Juan | D15: Jaidyn | E15: Doug | F15: Jaidyn | G15: Jaidyn | H15: CLOSED
B16: {=B13+7} -> 46202 | C16: =C13+7 -> 46203 | D16: =D13+7 -> 46204 | E16: =E13+7 -> 46205 | F16: =F13+7 -> 46206 | G16: =G13+7 -> 46207 | H16: =H13+7 -> 46208
B17: Gee | C17: Bergstrom
B18: Juan | C18: Juan
B19: {=B16+7} -> 46209 | C19: =C16+7 -> 46210 | D19: =D16+7 -> 46211 | E19: =E16+7 -> 46212 | F19: =F16+7 -> 46213 | G19: =G16+7 -> 46214 | H19: =H16+7 -> 46215
B23: =YEAR(TODAY()) -> 2026 | C23: JULY | E23: MONDAY | F23: La Verne | G23: Lockbox Code: | H23: SWC: Brian SDC: Dr. Bezzic
B24: CALENDAR YEAR | C24: CALENDAR MONTH | E24: FIRST DAY OF WEEK
B25: =TEXT(B26,"dddd") -> Monday | C25: =TEXT(C26,"dddd") -> Tuesday | D25: =TEXT(D26,"dddd") -> Wednesday | E25: =TEXT(E26,"dddd") -> Thursday | F25: =TEXT(F26,"dddd") -> Friday | G25: =TEXT(G26,"dddd") -> Saturday | H25: =TEXT(H26,"dddd") -> Sunday
B26: {=DATE($B$23,MATCH(UPPER($C$23),{"JANUARY","FEBRUARY","MARCH","APRIL","MAY","JUNE","JULY","AUGUST","SEPTEMBER","OCTOBER","NOVEMBER","DECEMBER"},0),1)-MOD(WEEKDAY(DATE($B$23,MATCH(UPPER($C$23),{"JANUARY","FEBRUARY","MARCH","APRIL","MAY","JUNE","JULY","AUGUST","SEPTEMBER","OCTOBER","NOVEMBER","DECEMBER"},0),1),2)-MATCH(UPPER($E$23),{"MONDAY","TUESDAY","WEDNESDAY","THURSDAY","FRIDAY","SATURDAY","SUNDAY"},0),7)} -> 46202 | C26: =B26+1 -> 46203 | D26: =C26+1 -> 46204 | E26: =D26+1 -> 46205 | F26: =E26+1 -> 46206 | G26: =F26+1 -> 46207 | H26: =G26+1 -> 46208
D27: Bergstrom | E27: Bergstrom | F27: Bergstrom | G27: CLOSED | H27: CLOSED
D28: Jaidyn | E28: Karen | F28: Jaidyn | G28: CLOSED | H28: CLOSED
B29: =B26+7 -> 46209 | C29: =C26+7 -> 46210 | D29: =D26+7 -> 46211 | E29: =E26+7 -> 46212 | F29: =F26+7 -> 46213 | G29: =G26+7 -> 46214 | H29: =H26+7 -> 46215
B30: Bergstrom | C30: Bergstrom | D30: Bergstrom | E30: Bergstrom | F30: Bergstrom | G30: Peng | H30: CLOSED
B31: Juan | C31: Juan | D31: Jaidyn | E31: Doug | F31: Jaidyn | G31: Jaidyn | H31: CLOSED
B32: =B29+7 -> 46216 | C32: =C29+7 -> 46217 | D32: =D29+7 -> 46218 | E32: =E29+7 -> 46219 | F32: =F29+7 -> 46220 | G32: =G29+7 -> 46221 | H32: =H29+7 -> 46222
B33: Bergstrom | C33: Bergstrom | D33: Bergstrom | E33: Bergstrom | F33: Bergstrom | G33: Peng | H33: CLOSED
B34: Juan | C34: Juan | D34: Jaidyn | E34: Doug | F34: Jaidyn | G34: Jaidyn | H34: CLOSED
B35: =B32+7 -> 46223 | C35: =C32+7 -> 46224 | D35: =D32+7 -> 46225 | E35: =E32+7 -> 46226 | F35: =F32+7 -> 46227 | G35: =G32+7 -> 46228 | H35: =H32+7 -> 46229
B36: Bergstrom | C36: Bergstrom | D36: Bergstrom | E36: Bergstrom | F36: Bergstrom | G36: Peng | H36: CLOSED
B37: Juan | C37: Juan | D37: Jaidyn | E37: Doug | F37: Jaidyn | G37: Jaidyn | H37: CLOSED
B38: =B35+7 -> 46230 | C38: =C35+7 -> 46231 | D38: =D35+7 -> 46232 | E38: =E35+7 -> 46233 | F38: =F35+7 -> 46234 | G38: =G35+7 -> 46235 | H38: =H35+7 -> 46236
B39: Bergstrom | C39: Bergstrom | D39: Bergstrom | E39: Bergstrom | F39: Bergstrom
B40: Juan | C40: Juan | D40: Jaidyn | E40: Doug | F40: Jaidyn
B41: =B38+7 -> 46237 | C41: =C38+7 -> 46238 | D41: =D38+7 -> 46239 | E41: =E38+7 -> 46240 | F41: =F38+7 -> 46241 | G41: =G38+7 -> 46242 | H41: =H38+7 -> 46243
B45: =YEAR(TODAY()) -> 2026 | C45: AUGUST | E45: MONDAY | F45: La Verne | G45: Lockbox Code: | H45: SWC: Brian SDC: Dr. Bezzic | I45: x
B46: CALENDAR YEAR | C46: CALENDAR MONTH | E46: FIRST DAY OF WEEK
...

Sheet Eastvale
B1: =YEAR(TODAY()) -> 2026 | C1: JUNE | E1: MONDAY | F1: Location: Eastvale | G1: Lockbox Code: | H1: SWC: Brian SDC: Dr. Bezzic | I1: x
B2: CALENDAR YEAR | C2: CALENDAR MONTH | E2: FIRST DAY OF WEEK
B3: {=TEXT(B4,"dddd")} -> Monday | C3: =TEXT(C4,"dddd") -> Tuesday | D3: =TEXT(D4,"dddd") -> Wednesday | E3: =TEXT(E4,"dddd") -> Thursday | F3: =TEXT(F4,"dddd") -> Friday | G3: =TEXT(G4,"dddd") -> Saturday | H3: =TEXT(H4,"dddd") -> Sunday
B4: {=DATE($B$1,MATCH(UPPER($C$1),{"JANUARY","FEBRUARY","MARCH","APRIL","MAY","JUNE","JULY","AUGUST","SEPTEMBER","OCTOBER","NOVEMBER","DECEMBER"},0),1)-MOD(WEEKDAY(DATE($B$1,MATCH(UPPER($C$1),{"JANUARY","FEBRUARY","MARCH","APRIL","MAY","JUNE","JULY","AUGUST","SEPTEMBER","OCTOBER","NOVEMBER","DECEMBER"},0),1),2)-MATCH(UPPER($E$1),{"MONDAY","TUESDAY","WEDNESDAY","THURSDAY","FRIDAY","SATURDAY","SUNDAY"},0),7)} -> 46174 | C4: =B4+1 -> 46175 | D4: =C4+1 -> 46176 | E4: =D4+1 -> 46177 | F4: =E4+1 -> 46178 | G4: =F4+1 -> 46179 | H4: =G4+1 -> 46180
B5: Vich | C5: Vich/Peng | D5: Vich/Garatti | E5: Vich | F5: Vich/Garatti | G5: Garatti | H5: Chapman
B6: Kendia | C6: Brian | D6: Kendia | E6: Kendia | F6: Brian | G6: Brian | H6: Claudia
B7: {=B4+7} -> 46181 | C7: =C4+7 -> 46182 | D7: =D4+7 -> 46183 | E7: =E4+7 -> 46184 | F7: =F4+7 -> 46185 | G7: =G4+7 -> 46186 | H7: =H4+7 -> 46187
B8: Vich/Garatti | C8: Vich | D8: Vich/Garatti | E8: Vich | F8: Vich/Garatti | G8: Garatti | H8: Chapman
B9: Steven | C9: Kendia | D9: Kendia | E9: Kendia | F9: Marissa | G9: Kendia | H9: Claudia
B10: {=B7+7} -> 46188 | C10: =C7+7 -> 46189 | D10: =D7+7 -> 46190 | E10: =E7+7 -> 46191 | F10: =F7+7 -> 46192 | G10: =G7+7 -> 46193 | H10: =H7+7 -> 46194
B11: Vich/Garatti | C11: Vich | D11: Vich/Garatti | E11: Vich | F11: Vich/Garatti | G11: Garatti | H11: Chapman
B12: Kendia | C12: Kendia | D12: Kendia | E12: Kendia | F12: Brian | G12: Brian | H12: Claudia
B13: {=B10+7} -> 46195 | C13: =C10+7 -> 46196 | D13: =D10+7 -> 46197 | E13: =E10+7 -> 46198 | F13: =F10+7 -> 46199 | G13: =G10+7 -> 46200 | H13: =H10+7 -> 46201
B14: Vich/Garatti | C14: Vich | D14: Vich/Garatti | E14: Vich | F14: Vich/Garatti | G14: Garatti | H14: Chapman
B15: Kendia | C15: Kendia | D15: Kendia | E15: Kendia | F15: Brian | G15: WC NEEDED | H15: Claudia
B16: {=B13+7} -> 46202 | C16: =C13+7 -> 46203 | D16: =D13+7 -> 46204 | E16: =E13+7 -> 46205 | F16: =F13+7 -> 46206 | G16: =G13+7 -> 46207 | H16: =H13+7 -> 46208
B17: Vich/Garatti | C17: Vich
B18: Kendia | C18: Kendia
B19: {=B16+7} -> 46209 | C19: =C16+7 -> 46210 | D19: =D16+7 -> 46211 | E19: =E16+7 -> 46212 | F19: =F16+7 -> 46213 | G19: =G16+7 -> 46214 | H19: =H16+7 -> 46215
B23: =YEAR(TODAY()) -> 2026 | C23: JULY | E23: MONDAY | F23: Location: Eastvale | G23: Lockbox Code: | H23: SWC: Brian SDC: Dr. Bezzic | I23: x
B24: CALENDAR YEAR | C24: CALENDAR MONTH | E24: FIRST DAY OF WEEK
B25: =TEXT(B26,"dddd") -> Monday | C25: =TEXT(C26,"dddd") -> Tuesday | D25: =TEXT(D26,"dddd") -> Wednesday | E25: =TEXT(E26,"dddd") -> Thursday | F25: =TEXT(F26,"dddd") -> Friday | G25: =TEXT(G26,"dddd") -> Saturday | H25: =TEXT(H26,"dddd") -> Sunday
B26: {=DATE($B$23,MATCH(UPPER($C$23),{"JANUARY","FEBRUARY","MARCH","APRIL","MAY","JUNE","JULY","AUGUST","SEPTEMBER","OCTOBER","NOVEMBER","DECEMBER"},0),1)-MOD(WEEKDAY(DATE($B$23,MATCH(UPPER($C$23),{"JANUARY","FEBRUARY","MARCH","APRIL","MAY","JUNE","JULY","AUGUST","SEPTEMBER","OCTOBER","NOVEMBER","DECEMBER"},0),1),2)-MATCH(UPPER($E$23),{"MONDAY","TUESDAY","WEDNESDAY","THURSDAY","FRIDAY","SATURDAY","SUNDAY"},0),7)} -> 46202 | C26: =B26+1 -> 46203 | D26: =C26+1 -> 46204 | E26: =D26+1 -> 46205 | F26: =E26+1 -> 46206 | G26: =F26+1 -> 46207 | H26: =G26+1 -> 46208
D27: Vich/Garratti | E27: Vich | F27: Vich/Garrati | G27: CLOSED | H27: Chapman
D28: Kendia | E28: Kendia | F28: Brian | G28: CLOSED | H28: Kendia
B29: =B26+7 -> 46209 | C29: =C26+7 -> 46210 | D29: =D26+7 -> 46211 | E29: =E26+7 -> 46212 | F29: =F26+7 -> 46213 | G29: =G26+7 -> 46214 | H29: =H26+7 -> 46215
B30: Vich/Garatti | C30: Vich | D30: Vich/Garratti | E30: Vich | F30: Vich/Garrati | G30: Garrati | H30: Chapman
B31: Kendia | C31: Kendia | D31: Kendia | E31: Kendia | F31: Brian | G31: Brian | H31: Kendia
B32: =B29+7 -> 46216 | C32: =C29+7 -> 46217 | D32: =D29+7 -> 46218 | E32: =E29+7 -> 46219 | F32: =F29+7 -> 46220 | G32: =G29+7 -> 46221 | H32: =H29+7 -> 46222
B33: Vich/Garatti | C33: Vich | D33: Vich/Garratti | E33: Vich | F33: Vich/Garrati | G33: Garrati | H33: Chapman
B34: Kendia | C34: Kendia | D34: Kendia | E34: Kendia | F34: Brian | G34: Brian | H34: Kendia
B35: =B32+7 -> 46223 | C35: =C32+7 -> 46224 | D35: =D32+7 -> 46225 | E35: =E32+7 -> 46226 | F35: =F32+7 -> 46227 | G35: =G32+7 -> 46228 | H35: =H32+7 -> 46229
B36: Vich/Garatti | C36: Vich | D36: Vich/Garratti | E36: Vich | F36: Vich/Garrati | G36: Garrati | H36: Chapman
B37: Kendia | C37: Kendia | D37: Kendia | E37: Kendia | F37: Brian | G37: Brian | H37: Kendia
B38: =B35+7 -> 46230 | C38: =C35+7 -> 46231 | D38: =D35+7 -> 46232 | E38: =E35+7 -> 46233 | F38: =F35+7 -> 46234 | G38: =G35+7 -> 46235 | H38: =H35+7 -> 46236
B39: Vich/Garatti | C39: Vich | D39: Vich/Garratti | E39: Vich | F39: Vich/Garratti
B40: Kendia | C40: Kendia | D40: Kendia | E40: Kendia | F40: Brian
B41: =B38+7 -> 46237 | C41: =C38+7 -> 46238 | D41: =D38+7 -> 46239 | E41: =E38+7 -> 46240 | F41: =F38+7 -> 46241 | G41: =G38+7 -> 46242 | H41: =H38+7 -> 46243
B45: =YEAR(TODAY()) -> 2026 | C45: AUGUST | E45: MONDAY | F45: Location: Eastvale | G45: Lockbox Code: | H45: SWC: Brian SDC: Dr. Bezzic | I45: x
B46: CALENDAR YEAR | C46: CALENDAR MONTH | E46: FIRST DAY OF WEEK
...

Sheet Moreno Valley
B1: =YEAR(TODAY()) -> 2026 | C1: JUNE | E1: MONDAY | F1: Location: Moreno Valley | G1: Lockbox Code: | H1: SWC: Brian SDC: Dr. Bezzic | I1: X
B2: CALENDAR YEAR | C2: CALENDAR MONTH | E2: FIRST DAY OF WEEK
B3: {=TEXT(B4,"dddd")} -> Monday | C3: =TEXT(C4,"dddd") -> Tuesday | D3: =TEXT(D4,"dddd") -> Wednesday | E3: =TEXT(E4,"dddd") -> Thursday | F3: =TEXT(F4,"dddd") -> Friday | G3: =TEXT(G4,"dddd") -> Saturday | H3: =TEXT(H4,"dddd") -> Sunday
B4: {=DATE($B$1,MATCH(UPPER($C$1),{"JANUARY","FEBRUARY","MARCH","APRIL","MAY","JUNE","JULY","AUGUST","SEPTEMBER","OCTOBER","NOVEMBER","DECEMBER"},0),1)-MOD(WEEKDAY(DATE($B$1,MATCH(UPPER($C$1),{"JANUARY","FEBRUARY","MARCH","APRIL","MAY","JUNE","JULY","AUGUST","SEPTEMBER","OCTOBER","NOVEMBER","DECEMBER"},0),1),2)-MATCH(UPPER($E$1),{"MONDAY","TUESDAY","WEDNESDAY","THURSDAY","FRIDAY","SATURDAY","SUNDAY"},0),7)} -> 46174 | C4: =B4+1 -> 46175 | D4: =C4+1 -> 46176 | E4: =D4+1 -> 46177 | F4: =E4+1 -> 46178 | G4: =F4+1 -> 46179 | H4: =G4+1 -> 46180
B5: Closed | C5: Rhoe | D5: Rhoe | E5: Rhoe | F5: Rhoe | G5: Rhoe | H5: Closed
B6: Closed | C6: Melinda | D6: Melinda | E6: Melinda | F6: Melinda | G6: Claudia | H6: Closed
B7: {=B4+7} -> 46181 | C7: =C4+7 -> 46182 | D7: =D4+7 -> 46183 | E7: =E4+7 -> 46184 | F7: =F4+7 -> 46185 | G7: =G4+7 -> 46186 | H7: =H4+7 -> 46187
B8: Closed | C8: Rhoe | D8: Rhoe | E8: Rhoe | F8: Rhoe | G8: Rhoe | H8: Closed
B9: CLOSED | C9: Melinda | D9: Melinda | E9: Melinda | F9: Melinda | G9: Claudia | H9: Closed
B10: {=B7+7} -> 46188 | C10: =C7+7 -> 46189 | D10: =D7+7 -> 46190 | E10: =E7+7 -> 46191 | F10: =F7+7 -> 46192 | G10: =G7+7 -> 46193 | H10: =H7+7 -> 46194
B11: Closed | C11: Rhoe | D11: Rhoe | E11: Rhoe | F11: Rhoe | G11: Rhoe | H11: Closed
B12: Closed | C12: Melinda | D12: Melinda | E12: Melinda | F12: Melinda | G12: Claudia | H12: Closed
B13: {=B10+7} -> 46195 | C13: =C10+7 -> 46196 | D13: =D10+7 -> 46197 | E13: =E10+7 -> 46198 | F13: =F10+7 -> 46199 | G13: =G10+7 -> 46200 | H13: =H10+7 -> 46201
B14: Closed | C14: Rhoe | D14: Rhoe | E14: Rhoe | F14: Rhoe | G14: Rhoe | H14: Closed
B15: Closed | C15: Melinda | D15: Melinda | E15: Melinda | F15: Melinda | G15: Claudia | H15: Closed
B16: {=B13+7} -> 46202 | C16: =C13+7 -> 46203 | D16: =D13+7 -> 46204 | E16: =E13+7 -> 46205 | F16: =F13+7 -> 46206 | G16: =G13+7 -> 46207 | H16: =H13+7 -> 46208
B17: Closed | C17: Rhoe | H17: Closed
B18: Closed | C18: Melinda | H18: Closed
B19: {=B16+7} -> 46209 | C19: =C16+7 -> 46210 | D19: =D16+7 -> 46211 | E19: =E16+7 -> 46212 | F19: =F16+7 -> 46213 | G19: =G16+7 -> 46214 | H19: =H16+7 -> 46215
B23: =YEAR(TODAY()) -> 2026 | C23: JULY | E23: MONDAY | F23: Location: Moreno Valley | G23: Lockbox Code: | H23: SWC: Brian SDC: Dr. Bezzic | I23: X
B24: CALENDAR YEAR | C24: CALENDAR MONTH | E24: FIRST DAY OF WEEK
B25: =TEXT(B26,"dddd") -> Monday | C25: =TEXT(C26,"dddd") -> Tuesday | D25: =TEXT(D26,"dddd") -> Wednesday | E25: =TEXT(E26,"dddd") -> Thursday | F25: =TEXT(F26,"dddd") -> Friday | G25: =TEXT(G26,"dddd") -> Saturday | H25: =TEXT(H26,"dddd") -> Sunday
B26: {=DATE($B$23,MATCH(UPPER($C$23),{"JANUARY","FEBRUARY","MARCH","APRIL","MAY","JUNE","JULY","AUGUST","SEPTEMBER","OCTOBER","NOVEMBER","DECEMBER"},0),1)-MOD(WEEKDAY(DATE($B$23,MATCH(UPPER($C$23),{"JANUARY","FEBRUARY","MARCH","APRIL","MAY","JUNE","JULY","AUGUST","SEPTEMBER","OCTOBER","NOVEMBER","DECEMBER"},0),1),2)-MATCH(UPPER($E$23),{"MONDAY","TUESDAY","WEDNESDAY","THURSDAY","FRIDAY","SATURDAY","SUNDAY"},0),7)} -> 46202 | C26: =B26+1 -> 46203 | D26: =C26+1 -> 46204 | E26: =D26+1 -> 46205 | F26: =E26+1 -> 46206 | G26: =F26+1 -> 46207 | H26: =G26+1 -> 46208
D27: Rhoe | E27: Rhoe | F27: Rhoe | G27: Closed | H27: Closed
D28: Melinda | E28: Melinda | F28: Melinda | G28: Closed | H28: Closed
B29: =B26+7 -> 46209 | C29: =C26+7 -> 46210 | D29: =D26+7 -> 46211 | E29: =E26+7 -> 46212 | F29: =F26+7 -> 46213 | G29: =G26+7 -> 46214 | H29: =H26+7 -> 46215
B30: Closed | C30: Rhoe | D30: Rhoe | E30: Rhoe | F30: Rhoe | G30: Rhoe | H30: Closed
B31: Closed | C31: Melinda | D31: Melinda | E31: Melinda | F31: Melinda | G31: Claudia | H31: Closed
B32: =B29+7 -> 46216 | C32: =C29+7 -> 46217 | D32: =D29+7 -> 46218 | E32: =E29+7 -> 46219 | F32: =F29+7 -> 46220 | G32: =G29+7 -> 46221 | H32: =H29+7 -> 46222
B33: Closed | C33: Rhoe | D33: Rhoe | E33: Rhoe | F33: Rhoe | G33: Rhoe | H33: Closed
B34: Closed | C34: Melinda | D34: Melinda | E34: Melinda | F34: Melinda | G34: Claudia | H34: Closed
B35: =B32+7 -> 46223 | C35: =C32+7 -> 46224 | D35: =D32+7 -> 46225 | E35: =E32+7 -> 46226 | F35: =F32+7 -> 46227 | G35: =G32+7 -> 46228 | H35: =H32+7 -> 46229
B36: Closed | C36: Rhoe | D36: Rhoe | E36: Rhoe | F36: Rhoe | G36: Rhoe | H36: Closed
B37: Closed | C37: Melinda | D37: Melinda | E37: Melinda | F37: Melinda | G37: Claudia | H37: Closed
B38: =B35+7 -> 46230 | C38: =C35+7 -> 46231 | D38: =D35+7 -> 46232 | E38: =E35+7 -> 46233 | F38: =F35+7 -> 46234 | G38: =G35+7 -> 46235 | H38: =H35+7 -> 46236
B39: Closed | C39: Rhoe | D39: Rhoe | E39: Rhoe
B40: Closed | C40: Melinda | D40: Melinda | E40: Melinda
B41: =B38+7 -> 46237 | C41: =C38+7 -> 46238 | D41: =D38+7 -> 46239 | E41: =E38+7 -> 46240 | F41: =F38+7 -> 46241 | G41: =G38+7 -> 46242 | H41: =H38+7 -> 46243
B45: =YEAR(TODAY()) -> 2026 | C45: AUGUST | E45: MONDAY | F45: Location: Moreno Valley | G45: Lockbox Code: | H45: SWC: Brian SDC: Dr. Bezzic
B46: CALENDAR YEAR | C46: CALENDAR MONTH | E46: FIRST DAY OF WEEK
...

Sheet Redlands
B1: =YEAR(TODAY()) -> 2026 | C1: JUNE | E1: MONDAY | F1: Location: Redlands | G1: Lockbox Code: | H1: SWC: Brian SDC: Dr. Bezzic | I1: x
B2: CALENDAR YEAR | C2: CALENDAR MONTH | E2: FIRST DAY OF WEEK
B3: {=TEXT(B4,"dddd")} -> Monday | C3: =TEXT(C4,"dddd") -> Tuesday | D3: =TEXT(D4,"dddd") -> Wednesday | E3: =TEXT(E4,"dddd") -> Thursday | F3: =TEXT(F4,"dddd") -> Friday | G3: =TEXT(G4,"dddd") -> Saturday | H3: =TEXT(H4,"dddd") -> Sunday
B4: {=DATE($B$1,MATCH(UPPER($C$1),{"JANUARY","FEBRUARY","MARCH","APRIL","MAY","JUNE","JULY","AUGUST","SEPTEMBER","OCTOBER","NOVEMBER","DECEMBER"},0),1)-MOD(WEEKDAY(DATE($B$1,MATCH(UPPER($C$1),{"JANUARY","FEBRUARY","MARCH","APRIL","MAY","JUNE","JULY","AUGUST","SEPTEMBER","OCTOBER","NOVEMBER","DECEMBER"},0),1),2)-MATCH(UPPER($E$1),{"MONDAY","TUESDAY","WEDNESDAY","THURSDAY","FRIDAY","SATURDAY","SUNDAY"},0),7)} -> 46174 | C4: =B4+1 -> 46175 | D4: =C4+1 -> 46176 | E4: =D4+1 -> 46177 | F4: =E4+1 -> 46178 | G4: =F4+1 -> 46179 | H4: =G4+1 -> 46180
B5: Carthron | C5: Delector | D5: Carthron | E5: Carthron/Delector | F5: Delector | G5: Carthron/Delector | H5: Danny
B6: Chantel | C6: Chantel | D6: Chantel | E6: Chantel | F6: Chantel | G6: Steven P. | H6: Steven P.
B7: {=B4+7} -> 46181 | C7: =C4+7 -> 46182 | D7: =D4+7 -> 46183 | E7: =E4+7 -> 46184 | F7: =F4+7 -> 46185 | G7: =G4+7 -> 46186 | H7: =H4+7 -> 46187
B8: Carthron | C8: Delector | D8: Carthron | E8: Carthron | F8: Carthron | G8: Carthron | H8: Lam
B9: Chantel | C9: Chantel | D9: Chantel | E9: Chantel | F9: Chantel | G9: Melinda | H9: Madi
B10: {=B7+7} -> 46188 | C10: =C7+7 -> 46189 | D10: =D7+7 -> 46190 | E10: =E7+7 -> 46191 | F10: =F7+7 -> 46192 | G10: =G7+7 -> 46193 | H10: =H7+7 -> 46194
B11: Carthron | C11: Peng | D11: Carthron | E11: Carthron | F11: Carthron | G11: Carthron | H11: DC Needed
B12: Chantel | C12: Chantel | D12: Chantel | E12: Chantel | F12: Chantel | G12: Steven P. | H12: Steven P.
B13: {=B10+7} -> 46195 | C13: =C10+7 -> 46196 | D13: =D10+7 -> 46197 | E13: =E10+7 -> 46198 | F13: =F10+7 -> 46199 | G13: =G10+7 -> 46200 | H13: =H10+7 -> 46201
B14: Carthron | C14: Carthron | D14: Carhtron | E14: DC Needed | F14: DC Needed | G14: Carthron | H14: Danny
B15: Chantel | C15: Chantel | D15: Chantel | E15: Chantel | F15: Chantel | G15: Steven P. | H15: Steven P.
B16: {=B13+7} -> 46202 | C16: =C13+7 -> 46203 | D16: =D13+7 -> 46204 | E16: =E13+7 -> 46205 | F16: =F13+7 -> 46206 | G16: =G13+7 -> 46207 | H16: =H13+7 -> 46208
B17: Carthron | C17: Carthron
B18: Chantel | C18: Chantel
B19: {=B16+7} -> 46209 | C19: =C16+7 -> 46210 | D19: =D16+7 -> 46211 | E19: =E16+7 -> 46212 | F19: =F16+7 -> 46213 | G19: =G16+7 -> 46214 | H19: =H16+7 -> 46215
B23: =YEAR(TODAY()) -> 2026 | C23: JULY | E23: MONDAY | F23: Location: Redlands | G23: Lockbox Code: | H23: SWC: Brian SDC: Dr. Bezzic | I23: x
B24: CALENDAR YEAR | C24: CALENDAR MONTH | E24: FIRST DAY OF WEEK
B25: =TEXT(B26,"dddd") -> Monday | C25: =TEXT(C26,"dddd") -> Tuesday | D25: =TEXT(D26,"dddd") -> Wednesday | E25: =TEXT(E26,"dddd") -> Thursday | F25: =TEXT(F26,"dddd") -> Friday | G25: =TEXT(G26,"dddd") -> Saturday | H25: =TEXT(H26,"dddd") -> Sunday
B26: {=DATE($B$23,MATCH(UPPER($C$23),{"JANUARY","FEBRUARY","MARCH","APRIL","MAY","JUNE","JULY","AUGUST","SEPTEMBER","OCTOBER","NOVEMBER","DECEMBER"},0),1)-MOD(WEEKDAY(DATE($B$23,MATCH(UPPER($C$23),{"JANUARY","FEBRUARY","MARCH","APRIL","MAY","JUNE","JULY","AUGUST","SEPTEMBER","OCTOBER","NOVEMBER","DECEMBER"},0),1),2)-MATCH(UPPER($E$23),{"MONDAY","TUESDAY","WEDNESDAY","THURSDAY","FRIDAY","SATURDAY","SUNDAY"},0),7)} -> 46202 | C26: =B26+1 -> 46203 | D26: =C26+1 -> 46204 | E26: =D26+1 -> 46205 | F26: =E26+1 -> 46206 | G26: =F26+1 -> 46207 | H26: =G26+1 -> 46208
D27: Carthron | E27: Carthron | F27: DC Needed | G27: Closed | H27: Danny
D28: Chantel | E28: Chantel | F28: Chantel | G28: Closed | H28: Steven P.
B29: =B26+7 -> 46209 | C29: =C26+7 -> 46210 | D29: =D26+7 -> 46211 | E29: =E26+7 -> 46212 | F29: =F26+7 -> 46213 | G29: =G26+7 -> 46214 | H29: =H26+7 -> 46215
B30: Carthron | C30: Delector | D30: Carthron | E30: Carthron/Delector | F30: Delector | G30: Carthon/Delector | H30: Danny
B31: Chantel | C31: Chantel | D31: Chantel | E31: Chantel | F31: Chantel | G31: Steven P. | H31: Steven P.
B32: =B29+7 -> 46216 | C32: =C29+7 -> 46217 | D32: =D29+7 -> 46218 | E32: =E29+7 -> 46219 | F32: =F29+7 -> 46220 | G32: =G29+7 -> 46221 | H32: =H29+7 -> 46222
B33: Carthron | C33: Delector | D33: Carthron | E33: Carthron/Delector | F33: Delector | G33: Carthon/Delector | H33: Danny
B34: Chantel | C34: Chantel | D34: Chantel | E34: Chantel | F34: Chantel | G34: Steven P. | H34: Steven P.
B35: =B32+7 -> 46223 | C35: =C32+7 -> 46224 | D35: =D32+7 -> 46225 | E35: =E32+7 -> 46226 | F35: =F32+7 -> 46227 | G35: =G32+7 -> 46228 | H35: =H32+7 -> 46229
B36: Carthron | C36: Delector | D36: Carthron | E36: Carthron/Delector | F36: Delector | G36: Carthon/Delector | H36: Danny
B37: Chantel | C37: Chantel | D37: Chantel | E37: Chantel | F37: Chantel | G37: Steven P. | H37: Steven P.
B38: =B35+7 -> 46230 | C38: =C35+7 -> 46231 | D38: =D35+7 -> 46232 | E38: =E35+7 -> 46233 | F38: =F35+7 -> 46234 | G38: =G35+7 -> 46235 | H38: =H35+7 -> 46236
B39: Carthron | C39: Delector | D39: Carthron | E39: Carthron/Delector | F39: Delector
B40: Chantel | C40: Chantel | D40: Chantel | E40: Chantel | F40: Chantel
B41: =B38+7 -> 46237 | C41: =C38+7 -> 46238 | D41: =D38+7 -> 46239 | E41: =E38+7 -> 46240 | F41: =F38+7 -> 46241 | G41: =G38+7 -> 46242 | H41: =H38+7 -> 46243
B45: =YEAR(TODAY()) -> 2026 | C45: AUGUST | E45: MONDAY | F45: Location: Redlands | G45: Lockbox Code: | H45: SWC: Brian SDC: Dr. Bezzic | I45: x
B46: CALENDAR YEAR | C46: CALENDAR MONTH | E46: FIRST DAY OF WEEK
...

Sheet Rialto
B1: =YEAR(TODAY()) -> 2026 | C1: JUNE | E1: MONDAY | F1: Location: Rialto | G1: Lockbox Code: | H1: SWC: Brian SDC: Dr. Bezzic | I1: x
B2: CALENDAR YEAR | C2: CALENDAR MONTH | E2: FIRST DAY OF WEEK
B3: {=TEXT(B4,"dddd")} -> Monday | C3: =TEXT(C4,"dddd") -> Tuesday | D3: =TEXT(D4,"dddd") -> Wednesday | E3: =TEXT(E4,"dddd") -> Thursday | F3: =TEXT(F4,"dddd") -> Friday | G3: =TEXT(G4,"dddd") -> Saturday | H3: =TEXT(H4,"dddd") -> Sunday
B4: {=DATE($B$1,MATCH(UPPER($C$1),{"JANUARY","FEBRUARY","MARCH","APRIL","MAY","JUNE","JULY","AUGUST","SEPTEMBER","OCTOBER","NOVEMBER","DECEMBER"},0),1)-MOD(WEEKDAY(DATE($B$1,MATCH(UPPER($C$1),{"JANUARY","FEBRUARY","MARCH","APRIL","MAY","JUNE","JULY","AUGUST","SEPTEMBER","OCTOBER","NOVEMBER","DECEMBER"},0),1),2)-MATCH(UPPER($E$1),{"MONDAY","TUESDAY","WEDNESDAY","THURSDAY","FRIDAY","SATURDAY","SUNDAY"},0),7)} -> 46174 | C4: =B4+1 -> 46175 | D4: =C4+1 -> 46176 | E4: =D4+1 -> 46177 | F4: =E4+1 -> 46178 | G4: =F4+1 -> 46179 | H4: =G4+1 -> 46180
B5: Tolbirt | C5: Moursalian | D5: Moursalian | E5: Moursalian | F5: Moursalian | G5: Moursalian | H5: Peng
B6: Karen/Madi | C6: Madi | D6: Marissa | E6: Madi | F6: Madi | G6: Marissa | H6: Marissa
B7: {=B4+7} -> 46181 | C7: =C4+7 -> 46182 | D7: =D4+7 -> 46183 | E7: =E4+7 -> 46184 | F7: =F4+7 -> 46185 | G7: =G4+7 -> 46186 | H7: =H4+7 -> 46187
B8: Tolbirt | C8: Moursalian | D8: Moursalian | E8: Moursalian | F8: Moursalian | G8: Moursalin 10-1/Peng 1:30-5 | H8: CLOSED
B9: Karen/Genesis | C9: Madi | D9: Marissa/Madi | E9: Madi | F9: Madi | G9: Marissa | H9: CLOSED
B10: {=B7+7} -> 46188 | C10: =C7+7 -> 46189 | D10: =D7+7 -> 46190 | E10: =E7+7 -> 46191 | F10: =F7+7 -> 46192 | G10: =G7+7 -> 46193 | H10: =H7+7 -> 46194
B11: Tolbirt | C11: Moursalian | D11: Moursalian | E11: Moursalian | F11: Moursalian | G11: Moursalian | H11: CLOSED
B12: Karen/Madi | C12: Madi | D12: Marissa | E12: Madi | F12: Madi | G12: Marissa | H12: CLOSED
B13: {=B10+7} -> 46195 | C13: =C10+7 -> 46196 | D13: =D10+7 -> 46197 | E13: =E10+7 -> 46198 | F13: =F10+7 -> 46199 | G13: =G10+7 -> 46200 | H13: =H10+7 -> 46201
B14: Tolbirt | C14: Moursalian | D14: Moursalian | E14: Moursalian | F14: DC Needed | G14: Peng | H14: CLOSED
B15: Karen/Madi | C15: Madi | D15: Marissa | E15: Madi | F15: Madi | G15: Marissa | H15: CLOSED
B16: {=B13+7} -> 46202 | C16: =C13+7 -> 46203 | D16: =D13+7 -> 46204 | E16: =E13+7 -> 46205 | F16: =F13+7 -> 46206 | G16: =G13+7 -> 46207 | H16: =H13+7 -> 46208
B17: Tolbirt | C17: Peng | H17: Peng
B18: Karen/Madi | C18: Madi | H18: Madi
B19: {=B16+7} -> 46209 | C19: =C16+7 -> 46210 | D19: =D16+7 -> 46211 | E19: =E16+7 -> 46212 | F19: =F16+7 -> 46213 | G19: =G16+7 -> 46214 | H19: =H16+7 -> 46215
B23: =YEAR(TODAY()) -> 2026 | C23: JULY | E23: MONDAY | F23: Location: Rialto | G23: Lockbox Code: | H23: SWC: Brian SDC: Dr. Bezzic | I23: x
B24: CALENDAR YEAR | C24: CALENDAR MONTH | E24: FIRST DAY OF WEEK
B25: =TEXT(B26,"dddd") -> Monday | C25: =TEXT(C26,"dddd") -> Tuesday | D25: =TEXT(D26,"dddd") -> Wednesday | E25: =TEXT(E26,"dddd") -> Thursday | F25: =TEXT(F26,"dddd") -> Friday | G25: =TEXT(G26,"dddd") -> Saturday | H25: =TEXT(H26,"dddd") -> Sunday
B26: {=DATE($B$23,MATCH(UPPER($C$23),{"JANUARY","FEBRUARY","MARCH","APRIL","MAY","JUNE","JULY","AUGUST","SEPTEMBER","OCTOBER","NOVEMBER","DECEMBER"},0),1)-MOD(WEEKDAY(DATE($B$23,MATCH(UPPER($C$23),{"JANUARY","FEBRUARY","MARCH","APRIL","MAY","JUNE","JULY","AUGUST","SEPTEMBER","OCTOBER","NOVEMBER","DECEMBER"},0),1),2)-MATCH(UPPER($E$23),{"MONDAY","TUESDAY","WEDNESDAY","THURSDAY","FRIDAY","SATURDAY","SUNDAY"},0),7)} -> 46202 | C26: =B26+1 -> 46203 | D26: =C26+1 -> 46204 | E26: =D26+1 -> 46205 | F26: =E26+1 -> 46206 | G26: =F26+1 -> 46207 | H26: =G26+1 -> 46208
D27: Moursalian | E27: Moursalian | F27: DC Needed | G27: Closed | H27: CLOSED
D28: Marissa | E28: Madi | F28: Madi | G28: Closed | H28: CLOSED
B29: =B26+7 -> 46209 | C29: =C26+7 -> 46210 | D29: =D26+7 -> 46211 | E29: =E26+7 -> 46212 | F29: =F26+7 -> 46213 | G29: =G26+7 -> 46214 | H29: =H26+7 -> 46215
B30: Tolbirt | C30: Moursalian | D30: Moursalian | E30: Moursalian | F30: Moursalian | G30: Moursalian | H30: CLOSED
B31: Karen/ Madi | C31: Madi | D31: Marissa | E31: Madi | F31: Madi | G31: Marissa | H31: CLOSED
B32: =B29+7 -> 46216 | C32: =C29+7 -> 46217 | D32: =D29+7 -> 46218 | E32: =E29+7 -> 46219 | F32: =F29+7 -> 46220 | G32: =G29+7 -> 46221 | H32: =H29+7 -> 46222
B33: Tolbirt | C33: Moursalian | D33: Moursalian | E33: Moursalian | F33: Moursalian | G33: Moursalian HALF DAY 10-130 | H33: CLOSED
B34: Karen/Madi | C34: Madi | D34: Marissa | E34: Madi | F34: Madi | G34: Madi | H34: CLOSED
B35: =B32+7 -> 46223 | C35: =C32+7 -> 46224 | D35: =D32+7 -> 46225 | E35: =E32+7 -> 46226 | F35: =F32+7 -> 46227 | G35: =G32+7 -> 46228 | H35: =H32+7 -> 46229
B36: Tolbirt | C36: Moursalian | D36: Moursalian | E36: Moursalian | F36: Moursalian | G36: Moursalian | H36: CLOSED
B37: Karen/Madi | C37: Madi | D37: Marissa | E37: Madi | F37: Madi | G37: Marissa | H37: CLOSED
B38: =B35+7 -> 46230 | C38: =C35+7 -> 46231 | D38: =D35+7 -> 46232 | E38: =E35+7 -> 46233 | F38: =F35+7 -> 46234 | G38: =G35+7 -> 46235 | H38: =H35+7 -> 46236
B39: Tolbirt | C39: DC needed | D39: Moursalian | E39: Moursalian | F39: Moursalian
B40: Karen/Madi | C40: Madi | D40: Marissa | E40: Madi | F40: Madi
B41: =B38+7 -> 46237 | C41: =C38+7 -> 46238 | D41: =D38+7 -> 46239 | E41: =E38+7 -> 46240 | F41: =F38+7 -> 46241 | G41: =G38+7 -> 46242 | H41: =H38+7 -> 46243
B45: =YEAR(TODAY()) -> 2026 | C45: AUGUST | E45: MONDAY | F45: Location: Rialto | G45: Lockbox Code: | H45: SWC: Brian SDC: Dr. Bezzic | I45: x
B46: CALENDAR YEAR | C46: CALENDAR MONTH | E46: FIRST DAY OF WEEK
...

Sheet Winery
B1: =YEAR(TODAY()) -> 2026 | C1: JUNE | E1: MONDAY | F1: Location: Winery | G1: Lockbox Code: | H1: SWC: Brian SDC: Dr. Bezzic | I1: x
B2: CALENDAR YEAR | C2: CALENDAR MONTH | E2: FIRST DAY OF WEEK
B3: {=TEXT(B4,"dddd")} -> Monday | C3: =TEXT(C4,"dddd") -> Tuesday | D3: =TEXT(D4,"dddd") -> Wednesday | E3: =TEXT(E4,"dddd") -> Thursday | F3: =TEXT(F4,"dddd") -> Friday | G3: =TEXT(G4,"dddd") -> Saturday | H3: =TEXT(H4,"dddd") -> Sunday
B4: {=DATE($B$1,MATCH(UPPER($C$1),{"JANUARY","FEBRUARY","MARCH","APRIL","MAY","JUNE","JULY","AUGUST","SEPTEMBER","OCTOBER","NOVEMBER","DECEMBER"},0),1)-MOD(WEEKDAY(DATE($B$1,MATCH(UPPER($C$1),{"JANUARY","FEBRUARY","MARCH","APRIL","MAY","JUNE","JULY","AUGUST","SEPTEMBER","OCTOBER","NOVEMBER","DECEMBER"},0),1),2)-MATCH(UPPER($E$1),{"MONDAY","TUESDAY","WEDNESDAY","THURSDAY","FRIDAY","SATURDAY","SUNDAY"},0),7)} -> 46174 | C4: =B4+1 -> 46175 | D4: =C4+1 -> 46176 | E4: =D4+1 -> 46177 | F4: =E4+1 -> 46178 | G4: =F4+1 -> 46179 | H4: =G4+1 -> 46180
B5: Tulloss | C5: Tulloss/Tolbirt | D5: Tulloss | E5: Tulloss | F5: Tolbirt | G5: Tolbirt/ Peng | H5: Tulloss
B6: Estrella | C6: Genesis | D6: Genesis | E6: Genesis | F6: Marissa | G6: Genesis | H6: Jaidyn
B7: {=B4+7} -> 46181 | C7: =C4+7 -> 46182 | D7: =D4+7 -> 46183 | E7: =E4+7 -> 46184 | F7: =F4+7 -> 46185 | G7: =G4+7 -> 46186 | H7: =H4+7 -> 46187
B8: Tulloss | C8: Tulloss/Tolbirt | D8: Tulloss | E8: Tulloss | F8: Tolbirt | G8: Tolbirt/Peng 10-12:30 | H8: Win
B9: Estrella | C9: Genesis | D9: Genesis | E9: Brian | F9: Genesis | G9: Madi | H9: WC Needed
B10: {=B7+7} -> 46188 | C10: =C7+7 -> 46189 | D10: =D7+7 -> 46190 | E10: =E7+7 -> 46191 | F10: =F7+7 -> 46192 | G10: =G7+7 -> 46193 | H10: =H7+7 -> 46194
B11: Tulloss | C11: Tulloss/Tolbirt | D11: Tulloss | E11: Tulloss | F11: Tolbirt | G11: Dr. Tolbirt | H11: CLOSED
B12: Estrella | C12: Genesis | D12: Genesis | E12: Genesis | F12: Genesis | G12: Genesis | H12: CLOSED
B13: {=B10+7} -> 46195 | C13: =C10+7 -> 46196 | D13: =D10+7 -> 46197 | E13: =E10+7 -> 46198 | F13: =F10+7 -> 46199 | G13: =G10+7 -> 46200 | H13: =H10+7 -> 46201
B14: Tulloss | C14: Tulloss/Tolbirt | D14: Tulloss | E14: Tulloss | F14: Tolbirt | G14: Tolbirt | H14: CLOSED
B15: Estrella | C15: Genesis | D15: Genesis | E15: Genesis | F15: Genesis | G15: Genesis | H15: CLOSED
B16: {=B13+7} -> 46202 | C16: =C13+7 -> 46203 | D16: =D13+7 -> 46204 | E16: =E13+7 -> 46205 | F16: =F13+7 -> 46206 | G16: =G13+7 -> 46207 | H16: =H13+7 -> 46208
B17: Tulloss | C17: Tulloss/Tolbirt
B18: Estrella | C18: Genesis
B19: {=B16+7} -> 46209 | C19: =C16+7 -> 46210 | D19: =D16+7 -> 46211 | E19: =E16+7 -> 46212 | F19: =F16+7 -> 46213 | G19: =G16+7 -> 46214 | H19: =H16+7 -> 46215
B23: =YEAR(TODAY()) -> 2026 | C23: JULY | E23: MONDAY | F23: Location: Winery | G23: Lockbox Code: | H23: SWC: Brian SDC: Dr. Bezzic | I23: x
B24: CALENDAR YEAR | C24: CALENDAR MONTH | E24: FIRST DAY OF WEEK
B25: =TEXT(B26,"dddd") -> Monday | C25: =TEXT(C26,"dddd") -> Tuesday | D25: =TEXT(D26,"dddd") -> Wednesday | E25: =TEXT(E26,"dddd") -> Thursday | F25: =TEXT(F26,"dddd") -> Friday | G25: =TEXT(G26,"dddd") -> Saturday | H25: =TEXT(H26,"dddd") -> Sunday
B26: {=DATE($B$23,MATCH(UPPER($C$23),{"JANUARY","FEBRUARY","MARCH","APRIL","MAY","JUNE","JULY","AUGUST","SEPTEMBER","OCTOBER","NOVEMBER","DECEMBER"},0),1)-MOD(WEEKDAY(DATE($B$23,MATCH(UPPER($C$23),{"JANUARY","FEBRUARY","MARCH","APRIL","MAY","JUNE","JULY","AUGUST","SEPTEMBER","OCTOBER","NOVEMBER","DECEMBER"},0),1),2)-MATCH(UPPER($E$23),{"MONDAY","TUESDAY","WEDNESDAY","THURSDAY","FRIDAY","SATURDAY","SUNDAY"},0),7)} -> 46202 | C26: =B26+1 -> 46203 | D26: =C26+1 -> 46204 | E26: =D26+1 -> 46205 | F26: =E26+1 -> 46206 | G26: =F26+1 -> 46207 | H26: =G26+1 -> 46208
D27: Tulloss | E27: Tulloss | F27: Tolbirt | G27: Closed | H27: CLOSED
D28: Genesis | E28: Genesis | F28: Genesis | G28: Closed | H28: CLOSED
B29: =B26+7 -> 46209 | C29: =C26+7 -> 46210 | D29: =D26+7 -> 46211 | E29: =E26+7 -> 46212 | F29: =F26+7 -> 46213 | G29: =G26+7 -> 46214 | H29: =H26+7 -> 46215
B30: Tulloss | C30: Tulloss/Tolbirt | D30: Tulloss | E30: Tulloss | F30: Tolbirt | G30: Tolbirt/DC Needed | H30: CLOSED
B31: Estrella | C31: Genesis | D31: Genesis | E31: Genesis | F31: Genesis | G31: Genesis | H31: CLOSED
B32: =B29+7 -> 46216 | C32: =C29+7 -> 46217 | D32: =D29+7 -> 46218 | E32: =E29+7 -> 46219 | F32: =F29+7 -> 46220 | G32: =G29+7 -> 46221 | H32: =H29+7 -> 46222
B33: Tulloss | C33: Tulloss/Tolbirt | D33: Tulloss | E33: Tulloss | F33: Tolbirt | G33: Tolbirt/DC Needed | H33: CLOSED
B34: Estrella | C34: Genesis | D34: Genesis | E34: Genesis | F34: Genesis | G34: Genesis | H34: CLOSED
B35: =B32+7 -> 46223 | C35: =C32+7 -> 46224 | D35: =D32+7 -> 46225 | E35: =E32+7 -> 46226 | F35: =F32+7 -> 46227 | G35: =G32+7 -> 46228 | H35: =H32+7 -> 46229
B36: Tulloss | C36: Tulloss/Tolbirt | D36: Tulloss | E36: Tulloss | F36: Tolbirt | G36: Tolbirt/Lam | H36: CLOSED
B37: Estrella | C37: Genesis | D37: Genesis | E37: Genesis | F37: Genesis | G37: Genesis | H37: CLOSED
B38: =B35+7 -> 46230 | C38: =C35+7 -> 46231 | D38: =D35+7 -> 46232 | E38: =E35+7 -> 46233 | F38: =F35+7 -> 46234 | G38: =G35+7 -> 46235 | H38: =H35+7 -> 46236
B39: Tulloss | C39: Tulloss/Tolbirt | D39: Tulloss | E39: Tulloss | F39: Tulloss
B40: Estrella | C40: Genesis | D40: Genesis | E40: Genesis | F40: Genesis
B41: =B38+7 -> 46237 | C41: =C38+7 -> 46238 | D41: =D38+7 -> 46239 | E41: =E38+7 -> 46240 | F41: =F38+7 -> 46241 | G41: =G38+7 -> 46242 | H41: =H38+7 -> 46243
B45: =YEAR(TODAY()) -> 2026 | C45: AUGUST | E45: MONDAY | F45: Location: Winery | G45: Lockbox Code: | H45: SWC: Brian SDC: Dr. Bezzic | I45: x
B46: CALENDAR YEAR | C46: CALENDAR MONTH | E46: FIRST DAY OF WEEK
...

Sheet So Co
B1: =YEAR(TODAY()) -> 2026 | C1: JUNE | E1: MONDAY | F1: Location: South Corona | G1: Lockbox Code: | H1: SWC: Brian SDC: Dr. Bezzic | I1: x
B2: CALENDAR YEAR | C2: CALENDAR MONTH | E2: FIRST DAY OF WEEK
B3: {=TEXT(B4,"dddd")} -> Monday | C3: =TEXT(C4,"dddd") -> Tuesday | D3: =TEXT(D4,"dddd") -> Wednesday | E3: =TEXT(E4,"dddd") -> Thursday | F3: =TEXT(F4,"dddd") -> Friday | G3: =TEXT(G4,"dddd") -> Saturday | H3: =TEXT(H4,"dddd") -> Sunday
B4: {=DATE($B$1,MATCH(UPPER($C$1),{"JANUARY","FEBRUARY","MARCH","APRIL","MAY","JUNE","JULY","AUGUST","SEPTEMBER","OCTOBER","NOVEMBER","DECEMBER"},0),1)-MOD(WEEKDAY(DATE($B$1,MATCH(UPPER($C$1),{"JANUARY","FEBRUARY","MARCH","APRIL","MAY","JUNE","JULY","AUGUST","SEPTEMBER","OCTOBER","NOVEMBER","DECEMBER"},0),1),2)-MATCH(UPPER($E$1),{"MONDAY","TUESDAY","WEDNESDAY","THURSDAY","FRIDAY","SATURDAY","SUNDAY"},0),7)} -> 46174 | C4: =B4+1 -> 46175 | D4: =C4+1 -> 46176 | E4: =D4+1 -> 46177 | F4: =E4+1 -> 46178 | G4: =F4+1 -> 46179 | H4: =G4+1 -> 46180
B5: Dr. Lam | C5: Dr.K | D5: Lam | E5: Peng | F5: Lam | G5: Lam | H5: Closed
B6: Mel | C6: Mel | D6: Mel | E6: Mel | F6: Estrella | G6: Mel | H6: Closed
B7: {=B4+7} -> 46181 | C7: =C4+7 -> 46182 | D7: =D4+7 -> 46183 | E7: =E4+7 -> 46184 | F7: =F4+7 -> 46185 | G7: =G4+7 -> 46186 | H7: =H4+7 -> 46187
B8: Dr. Lam | C8: Dr.K | D8: Lam | E8: Lam | F8: Dr.K | G8: Lam | H8: Closed
B9: Mel | C9: Mel | D9: Mel | E9: Mel | F9: Estrella | G9: Esterlla 10-1/ WC Needed Afternoon | H9: Closed
B10: {=B7+7} -> 46188 | C10: =C7+7 -> 46189 | D10: =D7+7 -> 46190 | E10: =E7+7 -> 46191 | F10: =F7+7 -> 46192 | G10: =G7+7 -> 46193 | H10: =H7+7 -> 46194
B11: Dr.K | C11: Dr.K | D11: Lam | E11: Lam | F11: Dr.K | G11: Chapman | H11: Closed
B12: Mel | C12: Mel | D12: Mel | E12: Mel | F12: Estrella | G12: Mel | H12: Closed
B13: {=B10+7} -> 46195 | C13: =C10+7 -> 46196 | D13: =D10+7 -> 46197 | E13: =E10+7 -> 46198 | F13: =F10+7 -> 46199 | G13: =G10+7 -> 46200 | H13: =H10+7 -> 46201
B14: DC Needed | C14: Dr.K | D14: DC Needed | E14: Peng | F14: Dr.K | G14: Dr. K | H14: Closed
B15: Mel | C15: Mel | D15: Mel | E15: Mel | F15: Estrella | G15: Mel | H15: Closed
B16: {=B13+7} -> 46202 | C16: =C13+7 -> 46203 | D16: =D13+7 -> 46204 | E16: =E13+7 -> 46205 | F16: =F13+7 -> 46206 | G16: =G13+7 -> 46207 | H16: =H13+7 -> 46208
B17: Dr. K | C17: Dr.K | H17: Closed
B18: Mel | C18: Mel | H18: Closed
B19: {=B16+7} -> 46209 | C19: =C16+7 -> 46210 | D19: =D16+7 -> 46211 | E19: =E16+7 -> 46212 | F19: =F16+7 -> 46213 | G19: =G16+7 -> 46214 | H19: =H16+7 -> 46215
B23: =YEAR(TODAY()) -> 2026 | C23: JULY | E23: MONDAY | F23: Location: South Corona | G23: Lockbox Code: | H23: SWC: Brian SDC: Dr. Bezzic | I23: x
B24: CALENDAR YEAR | C24: CALENDAR MONTH | E24: FIRST DAY OF WEEK
B25: =TEXT(B26,"dddd") -> Monday | C25: =TEXT(C26,"dddd") -> Tuesday | D25: =TEXT(D26,"dddd") -> Wednesday | E25: =TEXT(E26,"dddd") -> Thursday | F25: =TEXT(F26,"dddd") -> Friday | G25: =TEXT(G26,"dddd") -> Saturday | H25: =TEXT(H26,"dddd") -> Sunday
B26: {=DATE($B$23,MATCH(UPPER($C$23),{"JANUARY","FEBRUARY","MARCH","APRIL","MAY","JUNE","JULY","AUGUST","SEPTEMBER","OCTOBER","NOVEMBER","DECEMBER"},0),1)-MOD(WEEKDAY(DATE($B$23,MATCH(UPPER($C$23),{"JANUARY","FEBRUARY","MARCH","APRIL","MAY","JUNE","JULY","AUGUST","SEPTEMBER","OCTOBER","NOVEMBER","DECEMBER"},0),1),2)-MATCH(UPPER($E$23),{"MONDAY","TUESDAY","WEDNESDAY","THURSDAY","FRIDAY","SATURDAY","SUNDAY"},0),7)} -> 46202 | C26: =B26+1 -> 46203 | D26: =C26+1 -> 46204 | E26: =D26+1 -> 46205 | F26: =E26+1 -> 46206 | G26: =F26+1 -> 46207 | H26: =G26+1 -> 46208
D27: DC Needed | E27: Peng | F27: Dr.K | G27: Closed | H27: CLOSED
D28: Mel | E28: Mel | F28: Estrella | G28: Closed | H28: CLOSED
B29: =B26+7 -> 46209 | C29: =C26+7 -> 46210 | D29: =D26+7 -> 46211 | E29: =E26+7 -> 46212 | F29: =F26+7 -> 46213 | G29: =G26+7 -> 46214 | H29: =H26+7 -> 46215
B30: Andres | C30: Dr.K | D30: Andres | E30: Andres | F30: Dr.K | G30: Dr. K | H30: Closed
B31: Mel | C31: Mel | D31: Mel | E31: Mel | F31: Estrella | G31: Mel | H31: Closed
B32: =B29+7 -> 46216 | C32: =C29+7 -> 46217 | D32: =D29+7 -> 46218 | E32: =E29+7 -> 46219 | F32: =F29+7 -> 46220 | G32: =G29+7 -> 46221 | H32: =H29+7 -> 46222
B33: Andres | C33: Dr.K | D33: Andres | E33: Andres | F33: Dr.K | G33: Dr. K | H33: Closed
B34: Mel | C34: Mel | D34: Mel | E34: Mel | F34: Estrella | G34: Mel | H34: Closed
B35: =B32+7 -> 46223 | C35: =C32+7 -> 46224 | D35: =D32+7 -> 46225 | E35: =E32+7 -> 46226 | F35: =F32+7 -> 46227 | G35: =G32+7 -> 46228 | H35: =H32+7 -> 46229
B36: Andres | C36: Dr.K | D36: Andres | E36: Andres | F36: Dr.K | G36: Dr. K | H36: Closed
B37: Mel | C37: Mel | D37: Mel | E37: Mel | F37: Estrella | G37: WC Needed | H37: Closed
B38: =B35+7 -> 46230 | C38: =C35+7 -> 46231 | D38: =D35+7 -> 46232 | E38: =E35+7 -> 46233 | F38: =F35+7 -> 46234 | G38: =G35+7 -> 46235 | H38: =H35+7 -> 46236
B39: Andres | C39: Dr.K | D39: Andres | E39: Andres | F39: Dr.K
B40: WC Needed | C40: Mel | D40: Mel | E40: Mel | F40: Estrella
